Workbook

Sheet Today
A1: TODAY
A3: ▶ Open the "💪 Workout" menu (top bar) → "Start Today's Session" → pick your day.
A4: Your exercises will load here with weights already filled in. Just type the reps you hit, then "💪 Workout > Save Session".
A6: (Until you start a session, this tab is empty on purpose.)

Sheet Plan
A1: MAXIMAL-GROWTH PLAN — UPPER / LOWER, 4 DAYS
A2: Mon UA · Tue LA · Thu UB · Fri LB (rest Wed/Sat/Sun). ~45 min each. Every muscle trained 2×/week, 10+ sets/week. Run double progression (see Rules tab).
A4: DAY 1 — UPPER A (Mon)
A5: Exercise | B5: Sets | C5: Reps | D5: Type | E5: How / Why
A6: Bench Press | B6: 4 | C6: 5-8 | D6: Main | E6: Chest. AMRAP-ish last set.
A7: Barbell Row | B7: 4 | C7: 5-8 | D7: Main | E7: Back. Flat back, pull to belly.
A8: Overhead Press | B8: 3 | C8: 6-10 | D8: Compound | E8: Shoulders + triceps.
A9: Lateral Raise | B9: 3 | C9: 12-20 | D9: Iso | E9: Side delts. Light, high reps.
A10: Triceps Pushdown | B10: 3 | C10: 10-15 | D10: Iso | E10: SS with Lateral Raise to save time.
A11: Incline Curl | B11: 3 | C11: 10-15 | D11: Iso | E11: Biceps.
A13: DAY 2 — LOWER A (Tue)
A14: Exercise | B14: Sets | C14: Reps | D14: Type | E14: How / Why
A15: Squat | B15: 4 | C15: 5-8 | D15: Main | E15: Quads. To parallel.
A16: Leg Press | B16: 3 | C16: 8-12 | D16: Compound | E16: More quad volume, low back rests.
A17: Romanian Deadlift | B17: 3 | C17: 8-12 | D17: Compound | E17: Hamstrings + glutes.
A18: Lying Leg Curl | B18: 3 | C18: 10-15 | D18: Iso | E18: Hamstrings (knee flexion).
A19: Calf Raise | B19: 4 | C19: 10-15 | D19: Iso | E19: Calves.
A20: Hanging Leg Raise | B20: 3 | C20: 10-15 | D20: Core | E20: Abs + decompress after squats.
A22: DAY 3 — UPPER B (Thu)
A23: Exercise | B23: Sets | C23: Reps | D23: Type | E23: How / Why
A24: Incline Dumbbell Press | B24: 4 | C24: 8-12 | D24: Main | E24: Upper chest.
A25: Lat Pulldown | B25: 4 | C25: 6-10 | D25: Main | E25: Back width (or Pull-ups).
A26: Seated Cable Row | B26: 3 | C26: 8-12 | D26: Compound | E26: Mid-back thickness.
A27: DB Shoulder Press | B27: 3 | C27: 8-12 | D27: Compound | E27: Shoulders.
A28: Face Pull | B28: 3 | C28: 15-20 | D28: Iso | E28: Rear delts + posture.
A29: Hammer Curl | B29: 3 | C29: 10-15 | D29: Iso | E29: Biceps + forearm.
A31: DAY 4 — LOWER B (Fri)
A32: Exercise | B32: Sets | C32: Reps | D32: Type | E32: How / Why
A33: Deadlift | B33: 3 | C33: 5-8 | D33: Main | E33: Posterior chain. Only 3 sets (CNS-heavy).
A34: Front Squat | B34: 3 | C34: 8-12 | D34: Compound | E34: Quad-focused (or Hack Squat).
A35: Bulgarian Split Squat | B35: 3 | C35: 8-12 | D35: Compound | E35: Per leg. Quads + glutes + balance.
A36: Hip Thrust | B36: 3 | C36: 8-12 | D36: Compound | E36: Glutes at peak contraction.
A37: Seated Leg Curl | B37: 3 | C37: 10-15 | D37: Iso | E37: Hamstrings.
A38: Calf Raise | B38: 4 | C38: 10-15 | D38: Iso | E38: Calves.
A40: WEEKLY VOLUME CHECK (sets per muscle — target 10+)
A41: Muscle | B41: Direct Sets/Week | C41: In Zone? | E41: Notes
A42: Chest | B42: 8 | C42: ~10 w/ presses | E42: Bench 4 + Incline DB 4, plus indirect from OHP/DB press
A43: Back | B43: 11 | C43: YES | E43: Row 4 + Pulldown 4 + Cable Row 3
A44: Shoulders | B44: 12 | C44: YES | E44: OHP 3 + Lateral 3 + DB Press 3 + Face Pull 3 (all heads)
A45: Biceps | B45: 6 | C45: ~10 w/ pulls | E45: Curl 3 + Hammer 3, plus heavy indirect from rows/pulldowns
...

Sheet Rules
A1: PROGRESSION RULES — DOUBLE PROGRESSION
A2: Climb the rep range first, then add weight. Read top to bottom — this answers every "should I add weight or reps?" moment.
A4: THE CORE LOOP
A5: • | B5: Every exercise has a rep range (on the Plan tab). You work inside it.
A6: • | B6: ADD REPS when: you are inside the range but not yet at the top. Keep the weight, get 1+ more reps next time.
A7: • | B7: ADD WEIGHT when: you hit the TOP of the range on ALL your sets. Then bump the weight and drop back toward the bottom of the range.
A8: • | B8: When unsure: add a rep before you add a plate.
A10: HOW MUCH WEIGHT TO ADD
A11: • | B11: Upper-body lifts: +1.25–2.5 kg (smallest jump / microplates if you have them).
A12: • | B12: Lower-body lifts: +2.5–5 kg.
A13: • | B13: Isolations (curls, raises, pushdowns): smallest possible jump, then rebuild reps from the bottom.
A15: EFFORT — what makes a set "count"
A16: • | B16: Most sets: stop 2–3 reps short of failure (RIR 2–3). Log the RIR.
A17: • | B17: Last set of a safe exercise (machines, cables, curls): you may go to failure (RIR 0–1).
A18: • | B18: A set with 4+ reps left in the tank does NOT count toward growth. This is the rule your old 15-rep "too easy" sets broke.
A20: WHEN TO REDUCE / DELOAD
A21: • | B21: If a heavier set lands BELOW the bottom of the range: fine, it still counts. Only slow down if it happens on every set.
A22: • | B22: STALL = cannot add a rep or weight for 2–3 sessions straight on a lift. That is the signal, not a single bad day.
A23: • | B23: Planned deload every 8–12 weeks (or at a stall): one week at ~half the sets and easy weight (RPE 5–6). Keep all the movements. Come back and resume climbing.
A25: VOLUME (how you reach the maximal zone)
A26: • | B26: Target 10–20 hard sets per muscle per week. This plan starts you at the bottom of that band.
A27: • | B27: If recovery is good and you are progressing, the volume is right — do not chase more for its own sake.
A28: • | B28: If a muscle lags AND you are recovering well, add 1 set to it. If you feel beat up / sleep poorly, you are near your ceiling — hold or deload.
A30: WORKED EXAMPLE
A31: 1 | B31: Bench Press, range 5–8. You do 20 kg × 8, 8, 8 → all sets hit the top (8). Next session add weight: 22.5 kg.
A32: 2 | B32: At 22.5 kg you get 7, 6, 6 → not at the top yet. Keep 22.5 kg, push for more reps next time.
A33: 3 | B33: Sessions later you reach 22.5 kg × 8, 8, 8 → top again → go to 25 kg. That is the whole game, forever.

Sheet Log
A1: WORKOUT LOG
A2: Fill the blue columns only. Day codes: UA / LA / UB / LB. Grey columns calculate themselves.
A3: Date | B3: Day | C3: Exercise | D3: Weight (kg) | E3: Reps | F3: RIR | G3: Notes | H3: Volume | I3: Est.1RM
A4: 46181 | B4: UA | C4: Bench Press | D4: 20 | E4: 8 | F4: 2 | H4: =IF(AND(ISNUMBER(D4),ISNUMBER(E4)),D4*E4,0) -> 160 | I4: =IF(AND(ISNUMBER(D4),ISNUMBER(E4),E4>0),ROUND(D4*(1+E4/30),1),0) -> 25.3
A5: 46181 | B5: UA | C5: Bench Press | D5: 20 | E5: 8 | F5: 2 | H5: =IF(AND(ISNUMBER(D5),ISNUMBER(E5)),D5*E5,0) -> 160 | I5: =IF(AND(ISNUMBER(D5),ISNUMBER(E5),E5>0),ROUND(D5*(1+E5/30),1),0) -> 25.3
A6: 46181 | B6: UA | C6: Bench Press | D6: 20 | E6: 8 | F6: 1 | G6: all sets hit top | H6: =IF(AND(ISNUMBER(D6),ISNUMBER(E6)),D6*E6,0) -> 160 | I6: =IF(AND(ISNUMBER(D6),ISNUMBER(E6),E6>0),ROUND(D6*(1+E6/30),1),0) -> 25.3
A7: 46181 | B7: UA | C7: Barbell Row | D7: 40 | E7: 7 | F7: 2 | H7: =IF(AND(ISNUMBER(D7),ISNUMBER(E7)),D7*E7,0) -> 280 | I7: =IF(AND(ISNUMBER(D7),ISNUMBER(E7),E7>0),ROUND(D7*(1+E7/30),1),0) -> 49.3
A8: 46181 | B8: UA | C8: Barbell Row | D8: 40 | E8: 6 | F8: 2 | H8: =IF(AND(ISNUMBER(D8),ISNUMBER(E8)),D8*E8,0) -> 240 | I8: =IF(AND(ISNUMBER(D8),ISNUMBER(E8),E8>0),ROUND(D8*(1+E8/30),1),0) -> 48
A9: 46181 | B9: UA | C9: Barbell Row | D9: 40 | E9: 6 | F9: 1 | G9: not at top yet | H9: =IF(AND(ISNUMBER(D9),ISNUMBER(E9)),D9*E9,0) -> 240 | I9: =IF(AND(ISNUMBER(D9),ISNUMBER(E9),E9>0),ROUND(D9*(1+E9/30),1),0) -> 48
A10: 46181 | B10: UA | C10: Overhead Press | D10: 15 | E10: 9 | F10: 2 | H10: =IF(AND(ISNUMBER(D10),ISNUMBER(E10)),D10*E10,0) -> 135 | I10: =IF(AND(ISNUMBER(D10),ISNUMBER(E10),E10>0),ROUND(D10*(1+E10/30),1),0) -> 19.5
A11: 46181 | B11: UA | C11: Overhead Press | D11: 15 | E11: 8 | F11: 2 | H11: =IF(AND(ISNUMBER(D11),ISNUMBER(E11)),D11*E11,0) -> 120 | I11: =IF(AND(ISNUMBER(D11),ISNUMBER(E11),E11>0),ROUND(D11*(1+E11/30),1),0) -> 19
A12: 46181 | B12: UA | C12: Overhead Press | D12: 15 | E12: 8 | F12: 1 | H12: =IF(AND(ISNUMBER(D12),ISNUMBER(E12)),D12*E12,0) -> 120 | I12: =IF(AND(ISNUMBER(D12),ISNUMBER(E12),E12>0),ROUND(D12*(1+E12/30),1),0) -> 19
A13: 46182 | B13: LA | C13: Squat | D13: 30 | E13: 8 | F13: 2 | H13: =IF(AND(ISNUMBER(D13),ISNUMBER(E13)),D13*E13,0) -> 240 | I13: =IF(AND(ISNUMBER(D13),ISNUMBER(E13),E13>0),ROUND(D13*(1+E13/30),1),0) -> 38
A14: 46182 | B14: LA | C14: Squat | D14: 30 | E14: 8 | F14: 2 | H14: =IF(AND(ISNUMBER(D14),ISNUMBER(E14)),D14*E14,0) -> 240 | I14: =IF(AND(ISNUMBER(D14),ISNUMBER(E14),E14>0),ROUND(D14*(1+E14/30),1),0) -> 38
A15: 46182 | B15: LA | C15: Squat | D15: 30 | E15: 7 | F15: 1 | G15: one short of top | H15: =IF(AND(ISNUMBER(D15),ISNUMBER(E15)),D15*E15,0) -> 210 | I15: =IF(AND(ISNUMBER(D15),ISNUMBER(E15),E15>0),ROUND(D15*(1+E15/30),1),0) -> 37
A16: 46182 | B16: LA | C16: Leg Press | D16: 60 | E16: 12 | F16: 2 | H16: =IF(AND(ISNUMBER(D16),ISNUMBER(E16)),D16*E16,0) -> 720 | I16: =IF(AND(ISNUMBER(D16),ISNUMBER(E16),E16>0),ROUND(D16*(1+E16/30),1),0) -> 84
A17: 46182 | B17: LA | C17: Leg Press | D17: 60 | E17: 11 | F17: 2 | H17: =IF(AND(ISNUMBER(D17),ISNUMBER(E17)),D17*E17,0) -> 660 | I17: =IF(AND(ISNUMBER(D17),ISNUMBER(E17),E17>0),ROUND(D17*(1+E17/30),1),0) -> 82
A18: 46182 | B18: LA | C18: Romanian Deadlift | D18: 30 | E18: 11 | F18: 2 | H18: =IF(AND(ISNUMBER(D18),ISNUMBER(E18)),D18*E18,0) -> 330 | I18: =IF(AND(ISNUMBER(D18),ISNUMBER(E18),E18>0),ROUND(D18*(1+E18/30),1),0) -> 41
A19: 46182 | B19: LA | C19: Romanian Deadlift | D19: 30 | E19: 10 | F19: 2 | H19: =IF(AND(ISNUMBER(D19),ISNUMBER(E19)),D19*E19,0) -> 300 | I19: =IF(AND(ISNUMBER(D19),ISNUMBER(E19),E19>0),ROUND(D19*(1+E19/30),1),0) -> 40
H20: =IF(AND(ISNUMBER(D20),ISNUMBER(E20)),D20*E20,0) -> 0 | I20: =IF(AND(ISNUMBER(D20),ISNUMBER(E20),E20>0),ROUND(D20*(1+E20/30),1),0) -> 0
H21: =IF(AND(ISNUMBER(D21),ISNUMBER(E21)),D21*E21,0) -> 0 | I21: =IF(AND(ISNUMBER(D21),ISNUMBER(E21),E21>0),ROUND(D21*(1+E21/30),1),0) -> 0
H22: =IF(AND(ISNUMBER(D22),ISNUMBER(E22)),D22*E22,0) -> 0 | I22: =IF(AND(ISNUMBER(D22),ISNUMBER(E22),E22>0),ROUND(D22*(1+E22/30),1),0) -> 0
H23: =IF(AND(ISNUMBER(D23),ISNUMBER(E23)),D23*E23,0) -> 0 | I23: =IF(AND(ISNUMBER(D23),ISNUMBER(E23),E23>0),ROUND(D23*(1+E23/30),1),0) -> 0
H24: =IF(AND(ISNUMBER(D24),ISNUMBER(E24)),D24*E24,0) -> 0 | I24: =IF(AND(ISNUMBER(D24),ISNUMBER(E24),E24>0),ROUND(D24*(1+E24/30),1),0) -> 0
H25: =IF(AND(ISNUMBER(D25),ISNUMBER(E25)),D25*E25,0) -> 0 | I25: =IF(AND(ISNUMBER(D25),ISNUMBER(E25),E25>0),ROUND(D25*(1+E25/30),1),0) -> 0
H26: =IF(AND(ISNUMBER(D26),ISNUMBER(E26)),D26*E26,0) -> 0 | I26: =IF(AND(ISNUMBER(D26),ISNUMBER(E26),E26>0),ROUND(D26*(1+E26/30),1),0) -> 0
H27: =IF(AND(ISNUMBER(D27),ISNUMBER(E27)),D27*E27,0) -> 0 | I27: =IF(AND(ISNUMBER(D27),ISNUMBER(E27),E27>0),ROUND(D27*(1+E27/30),1),0) -> 0
H28: =IF(AND(ISNUMBER(D28),ISNUMBER(E28)),D28*E28,0) -> 0 | I28: =IF(AND(ISNUMBER(D28),ISNUMBER(E28),E28>0),ROUND(D28*(1+E28/30),1),0) -> 0
H29: =IF(AND(ISNUMBER(D29),ISNUMBER(E29)),D29*E29,0) -> 0 | I29: =IF(AND(ISNUMBER(D29),ISNUMBER(E29),E29>0),ROUND(D29*(1+E29/30),1),0) -> 0
H30: =IF(AND(ISNUMBER(D30),ISNUMBER(E30)),D30*E30,0) -> 0 | I30: =IF(AND(ISNUMBER(D30),ISNUMBER(E30),E30>0),ROUND(D30*(1+E30/30),1),0) -> 0
H31: =IF(AND(ISNUMBER(D31),ISNUMBER(E31)),D31*E31,0) -> 0 | I31: =IF(AND(ISNUMBER(D31),ISNUMBER(E31),E31>0),ROUND(D31*(1+E31/30),1),0) -> 0
... H503: =IF(AND(ISNUMBER(D503),ISNUMBER(E503)),D503*E503,0) -> 0 | I503: =IF(AND(ISNUMBER(D503),ISNUMBER(E503),E503>0),ROUND(D503*(1+E503/30),1),0) -> 0

Sheet Progress
A1: PROGRESS & NEXT MOVE
A2: "Next Move" reads your last session and tells you the double-progression call. ⬆ = hit top of range on all sets, add weight. ➕ = climb reps first.
A3: Exercise | B3: Rep Range | C3: Best Est.1RM (kg) | D3: Last Weight (kg) | E3: Last Session — Lowest Reps | F3: Next Move
A4: Bench Press | B4: 5-8 | C4: =IFERROR(IF(SUMPRODUCT(MAX((Log!$C$4:$C$503=A4)*Log!$I$4:$I$503))=0,"—",SUMPRODUCT(MAX((Log!$C$4:$C$503=A4)*Log!$I$4:$I$503))),"—") -> 25.3 | D4: =IFERROR(IF(I4="","—",SUMPRODUCT(MAX((Log!$C$4:$C$503=A4)*(Log!$A$4:$A$503=I4)*Log!$D$4:$D$503))),"—") -> 20 | E4: =IFERROR(IF(I4="","—",-SUMPRODUCT(MAX((Log!$C$4:$C$503=A4)*(Log!$A$4:$A$503=I4)*(-Log!$E$4:$E$503)-(1-(Log!$C$4:$C$503=A4)*(Log!$A$4:$A$503=I4))*9999))),"—") -> 8 | F4: =IF(I4="","not logged yet",IF(E4>=H4,"⬆ Add weight next session","➕ Add a rep (same weight)")) -> ⬆ Add weight next session | H4: 8 | I4: =IFERROR(IF(SUMPRODUCT(MAX((Log!$C$4:$C$503=A4)*Log!$A$4:$A$503))=0,"",SUMPRODUCT(MAX((Log!$C$4:$C$503=A4)*Log!$A$4:$A$503))),"") -> 46181
A5: Barbell Row | B5: 5-8 | C5: =IFERROR(IF(SUMPRODUCT(MAX((Log!$C$4:$C$503=A5)*Log!$I$4:$I$503))=0,"—",SUMPRODUCT(MAX((Log!$C$4:$C$503=A5)*Log!$I$4:$I$503))),"—") -> 49.3 | D5: =IFERROR(IF(I5="","—",SUMPRODUCT(MAX((Log!$C$4:$C$503=A5)*(Log!$A$4:$A$503=I5)*Log!$D$4:$D$503))),"—") -> 40 | E5: =IFERROR(IF(I5="","—",-SUMPRODUCT(MAX((Log!$C$4:$C$503=A5)*(Log!$A$4:$A$503=I5)*(-Log!$E$4:$E$503)-(1-(Log!$C$4:$C$503=A5)*(Log!$A$4:$A$503=I5))*9999))),"—") -> 6 | F5: =IF(I5="","not logged yet",IF(E5>=H5,"⬆ Add weight next session","➕ Add a rep (same weight)")) -> ➕ Add a rep (same weight) | H5: 8 | I5: =IFERROR(IF(SUMPRODUCT(MAX((Log!$C$4:$C$503=A5)*Log!$A$4:$A$503))=0,"",SUMPRODUCT(MAX((Log!$C$4:$C$503=A5)*Log!$A$4:$A$503))),"") -> 46181
A6: Overhead Press | B6: 6-10 | C6: =IFERROR(IF(SUMPRODUCT(MAX((Log!$C$4:$C$503=A6)*Log!$I$4:$I$503))=0,"—",SUMPRODUCT(MAX((Log!$C$4:$C$503=A6)*Log!$I$4:$I$503))),"—") -> 19.5 | D6: =IFERROR(IF(I6="","—",SUMPRODUCT(MAX((Log!$C$4:$C$503=A6)*(Log!$A$4:$A$503=I6)*Log!$D$4:$D$503))),"—") -> 15 | E6: =IFERROR(IF(I6="","—",-SUMPRODUCT(MAX((Log!$C$4:$C$503=A6)*(Log!$A$4:$A$503=I6)*(-Log!$E$4:$E$503)-(1-(Log!$C$4:$C$503=A6)*(Log!$A$4:$A$503=I6))*9999))),"—") -> 8 | F6: =IF(I6="","not logged yet",IF(E6>=H6,"⬆ Add weight next session","➕ Add a rep (same weight)")) -> ➕ Add a rep (same weight) | H6: 10 | I6: =IFERROR(IF(SUMPRODUCT(MAX((Log!$C$4:$C$503=A6)*Log!$A$4:$A$503))=0,"",SUMPRODUCT(MAX((Log!$C$4:$C$503=A6)*Log!$A$4:$A$503))),"") -> 46181
A7: Incline Dumbbell Press | B7: 8-12 | C7: =IFERROR(IF(SUMPRODUCT(MAX((Log!$C$4:$C$503=A7)*Log!$I$4:$I$503))=0,"—",SUMPRODUCT(MAX((Log!$C$4:$C$503=A7)*Log!$I$4:$I$503))),"—") -> — | D7: =IFERROR(IF(I7="","—",SUMPRODUCT(MAX((Log!$C$4:$C$503=A7)*(Log!$A$4:$A$503=I7)*Log!$D$4:$D$503))),"—") -> — | E7: =IFERROR(IF(I7="","—",-SUMPRODUCT(MAX((Log!$C$4:$C$503=A7)*(Log!$A$4:$A$503=I7)*(-Log!$E$4:$E$503)-(1-(Log!$C$4:$C$503=A7)*(Log!$A$4:$A$503=I7))*9999))),"—") -> — | F7: =IF(I7="","not logged yet",IF(E7>=H7,"⬆ Add weight next session","➕ Add a rep (same weight)")) -> not logged yet | H7: 12 | I7: =IFERROR(IF(SUMPRODUCT(MAX((Log!$C$4:$C$503=A7)*Log!$A$4:$A$503))=0,"",SUMPRODUCT(MAX((Log!$C$4:$C$503=A7)*Log!$A$4:$A$503))),"")
A8: Lat Pulldown | B8: 6-10 | C8: =IFERROR(IF(SUMPRODUCT(MAX((Log!$C$4:$C$503=A8)*Log!$I$4:$I$503))=0,"—",SUMPRODUCT(MAX((Log!$C$4:$C$503=A8)*Log!$I$4:$I$503))),"—") -> — | D8: =IFERROR(IF(I8="","—",SUMPRODUCT(MAX((Log!$C$4:$C$503=A8)*(Log!$A$4:$A$503=I8)*Log!$D$4:$D$503))),"—") -> — | E8: =IFERROR(IF(I8="","—",-SUMPRODUCT(MAX((Log!$C$4:$C$503=A8)*(Log!$A$4:$A$503=I8)*(-Log!$E$4:$E$503)-(1-(Log!$C$4:$C$503=A8)*(Log!$A$4:$A$503=I8))*9999))),"—") -> — | F8: =IF(I8="","not logged yet",IF(E8>=H8,"⬆ Add weight next session","➕ Add a rep (same weight)")) -> not logged yet | H8: 10 | I8: =IFERROR(IF(SUMPRODUCT(MAX((Log!$C$4:$C$503=A8)*Log!$A$4:$A$503))=0,"",SUMPRODUCT(MAX((Log!$C$4:$C$503=A8)*Log!$A$4:$A$503))),"")
A9: Seated Cable Row | B9: 8-12 | C9: =IFERROR(IF(SUMPRODUCT(MAX((Log!$C$4:$C$503=A9)*Log!$I$4:$I$503))=0,"—",SUMPRODUCT(MAX((Log!$C$4:$C$503=A9)*Log!$I$4:$I$503))),"—") -> — | D9: =IFERROR(IF(I9="","—",SUMPRODUCT(MAX((Log!$C$4:$C$503=A9)*(Log!$A$4:$A$503=I9)*Log!$D$4:$D$503))),"—") -> — | E9: =IFERROR(IF(I9="","—",-SUMPRODUCT(MAX((Log!$C$4:$C$503=A9)*(Log!$A$4:$A$503=I9)*(-Log!$E$4:$E$503)-(1-(Log!$C$4:$C$503=A9)*(Log!$A$4:$A$503=I9))*9999))),"—") -> — | F9: =IF(I9="","not logged yet",IF(E9>=H9,"⬆ Add weight next session","➕ Add a rep (same weight)")) -> not logged yet | H9: 12 | I9: =IFERROR(IF(SUMPRODUCT(MAX((Log!$C$4:$C$503=A9)*Log!$A$4:$A$503))=0,"",SUMPRODUCT(MAX((Log!$C$4:$C$503=A9)*Log!$A$4:$A$503))),"")
A10: DB Shoulder Press | B10: 8-12 | C10: =IFERROR(IF(SUMPRODUCT(MAX((Log!$C$4:$C$503=A10)*Log!$I$4:$I$503))=0,"—",SUMPRODUCT(MAX((Log!$C$4:$C$503=A10)*Log!$I$4:$I$503))),"—") -> — | D10: =IFERROR(IF(I10="","—",SUMPRODUCT(MAX((Log!$C$4:$C$503=A10)*(Log!$A$4:$A$503=I10)*Log!$D$4:$D$503))),"—") -> — | E10: =IFERROR(IF(I10="","—",-SUMPRODUCT(MAX((Log!$C$4:$C$503=A10)*(Log!$A$4:$A$503=I10)*(-Log!$E$4:$E$503)-(1-(Log!$C$4:$C$503=A10)*(Log!$A$4:$A$503=I10))*9999))),"—") -> — | F10: =IF(I10="","not logged yet",IF(E10>=H10,"⬆ Add weight next session","➕ Add a rep (same weight)")) -> not logged yet | H10: 12 | I10: =IFERROR(IF(SUMPRODUCT(MAX((Log!$C$4:$C$503=A10)*Log!$A$4:$A$503))=0,"",SUMPRODUCT(MAX((Log!$C$4:$C$503=A10)*Log!$A$4:$A$503))),"")
A11: Squat | B11: 5-8 | C11: =IFERROR(IF(SUMPRODUCT(MAX((Log!$C$4:$C$503=A11)*Log!$I$4:$I$503))=0,"—",SUMPRODUCT(MAX((Log!$C$4:$C$503=A11)*Log!$I$4:$I$503))),"—") -> 38 | D11: =IFERROR(IF(I11="","—",SUMPRODUCT(MAX((Log!$C$4:$C$503=A11)*(Log!$A$4:$A$503=I11)*Log!$D$4:$D$503))),"—") -> 30 | E11: =IFERROR(IF(I11="","—",-SUMPRODUCT(MAX((Log!$C$4:$C$503=A11)*(Log!$A$4:$A$503=I11)*(-Log!$E$4:$E$503)-(1-(Log!$C$4:$C$503=A11)*(Log!$A$4:$A$503=I11))*9999))),"—") -> 7 | F11: =IF(I11="","not logged yet",IF(E11>=H11,"⬆ Add weight next session","➕ Add a rep (same weight)")) -> ➕ Add a rep (same weight) | H11: 8 | I11: =IFERROR(IF(SUMPRODUCT(MAX((Log!$C$4:$C$503=A11)*Log!$A$4:$A$503))=0,"",SUMPRODUCT(MAX((Log!$C$4:$C$503=A11)*Log!$A$4:$A$503))),"") -> 46182
A12: Leg Press | B12: 8-12 | C12: =IFERROR(IF(SUMPRODUCT(MAX((Log!$C$4:$C$503=A12)*Log!$I$4:$I$503))=0,"—",SUMPRODUCT(MAX((Log!$C$4:$C$503=A12)*Log!$I$4:$I$503))),"—") -> 84 | D12: =IFERROR(IF(I12="","—",SUMPRODUCT(MAX((Log!$C$4:$C$503=A12)*(Log!$A$4:$A$503=I12)*Log!$D$4:$D$503))),"—") -> 60 | E12: =IFERROR(IF(I12="","—",-SUMPRODUCT(MAX((Log!$C$4:$C$503=A12)*(Log!$A$4:$A$503=I12)*(-Log!$E$4:$E$503)-(1-(Log!$C$4:$C$503=A12)*(Log!$A$4:$A$503=I12))*9999))),"—") -> 11 | F12: =IF(I12="","not logged yet",IF(E12>=H12,"⬆ Add weight next session","➕ Add a rep (same weight)")) -> ➕ Add a rep (same weight) | H12: 12 | I12: =IFERROR(IF(SUMPRODUCT(MAX((Log!$C$4:$C$503=A12)*Log!$A$4:$A$503))=0,"",SUMPRODUCT(MAX((Log!$C$4:$C$503=A12)*Log!$A$4:$A$503))),"") -> 46182
A13: Romanian Deadlift | B13: 8-12 | C13: =IFERROR(IF(SUMPRODUCT(MAX((Log!$C$4:$C$503=A13)*Log!$I$4:$I$503))=0,"—",SUMPRODUCT(MAX((Log!$C$4:$C$503=A13)*Log!$I$4:$I$503))),"—") -> 41 | D13: =IFERROR(IF(I13="","—",SUMPRODUCT(MAX((Log!$C$4:$C$503=A13)*(Log!$A$4:$A$503=I13)*Log!$D$4:$D$503))),"—") -> 30 | E13: =IFERROR(IF(I13="","—",-SUMPRODUCT(MAX((Log!$C$4:$C$503=A13)*(Log!$A$4:$A$503=I13)*(-Log!$E$4:$E$503)-(1-(Log!$C$4:$C$503=A13)*(Log!$A$4:$A$503=I13))*9999))),"—") -> 10 | F13: =IF(I13="","not logged yet",IF(E13>=H13,"⬆ Add weight next session","➕ Add a rep (same weight)")) -> ➕ Add a rep (same weight) | H13: 12 | I13: =IFERROR(IF(SUMPRODUCT(MAX((Log!$C$4:$C$503=A13)*Log!$A$4:$A$503))=0,"",SUMPRODUCT(MAX((Log!$C$4:$C$503=A13)*Log!$A$4:$A$503))),"") -> 46182
A14: Deadlift | B14: 5-8 | C14: =IFERROR(IF(SUMPRODUCT(MAX((Log!$C$4:$C$503=A14)*Log!$I$4:$I$503))=0,"—",SUMPRODUCT(MAX((Log!$C$4:$C$503=A14)*Log!$I$4:$I$503))),"—") -> — | D14: =IFERROR(IF(I14="","—",SUMPRODUCT(MAX((Log!$C$4:$C$503=A14)*(Log!$A$4:$A$503=I14)*Log!$D$4:$D$503))),"—") -> — | E14: =IFERROR(IF(I14="","—",-SUMPRODUCT(MAX((Log!$C$4:$C$503=A14)*(Log!$A$4:$A$503=I14)*(-Log!$E$4:$E$503)-(1-(Log!$C$4:$C$503=A14)*(Log!$A$4:$A$503=I14))*9999))),"—") -> — | F14: =IF(I14="","not logged yet",IF(E14>=H14,"⬆ Add weight next session","➕ Add a rep (same weight)")) -> not logged yet | H14: 8 | I14: =IFERROR(IF(SUMPRODUCT(MAX((Log!$C$4:$C$503=A14)*Log!$A$4:$A$503))=0,"",SUMPRODUCT(MAX((Log!$C$4:$C$503=A14)*Log!$A$4:$A$503))),"")
A15: Front Squat | B15: 8-12 | C15: =IFERROR(IF(SUMPRODUCT(MAX((Log!$C$4:$C$503=A15)*Log!$I$4:$I$503))=0,"—",SUMPRODUCT(MAX((Log!$C$4:$C$503=A15)*Log!$I$4:$I$503))),"—") -> — | D15: =IFERROR(IF(I15="","—",SUMPRODUCT(MAX((Log!$C$4:$C$503=A15)*(Log!$A$4:$A$503=I15)*Log!$D$4:$D$503))),"—") -> — | E15: =IFERROR(IF(I15="","—",-SUMPRODUCT(MAX((Log!$C$4:$C$503=A15)*(Log!$A$4:$A$503=I15)*(-Log!$E$4:$E$503)-(1-(Log!$C$4:$C$503=A15)*(Log!$A$4:$A$503=I15))*9999))),"—") -> — | F15: =IF(I15="","not logged yet",IF(E15>=H15,"⬆ Add weight next session","➕ Add a rep (same weight)")) -> not logged yet | H15: 12 | I15: =IFERROR(IF(SUMPRODUCT(MAX((Log!$C$4:$C$503=A15)*Log!$A$4:$A$503))=0,"",SUMPRODUCT(MAX((Log!$C$4:$C$503=A15)*Log!$A$4:$A$503))),"")
... A17: Hip Thrust | B17: 8-12 | C17: =IFERROR(IF(SUMPRODUCT(MAX((Log!$C$4:$C$503=A17)*Log!$I$4:$I$503))=0,"—",SUMPRODUCT(MAX((Log!$C$4:$C$503=A17)*Log!$I$4:$I$503))),"—") -> — | D17: =IFERROR(IF(I17="","—",SUMPRODUCT(MAX((Log!$C$4:$C$503=A17)*(Log!$A$4:$A$503=I17)*Log!$D$4:$D$503))),"—") -> — | E17: =IFERROR(IF(I17="","—",-SUMPRODUCT(MAX((Log!$C$4:$C$503=A17)*(Log!$A$4:$A$503=I17)*(-Log!$E$4:$E$503)-(1-(Log!$C$4:$C$503=A17)*(Log!$A$4:$A$503=I17))*9999))),"—") -> — | F17: =IF(I17="","not logged yet",IF(E17>=H17,"⬆ Add weight next session","➕ Add a rep (same weight)")) -> not logged yet | H17: 12 | I17: =IFERROR(IF(SUMPRODUCT(MAX((Log!$C$4:$C$503=A17)*Log!$A$4:$A$503))=0,"",SUMPRODUCT(MAX((Log!$C$4:$C$503=A17)*Log!$A$4:$A$503))),"")

Sheet Setup
A1: ONE-TIME SETUP (turns on the automation)
A3: 1 | B3: Open this file in Google Sheets (in Google Drive: right-click the file → Open with → Google Sheets, or File → Import).
A4: 2 | B4: In Google Sheets, go to the top menu: Extensions → Apps Script.
A5: 3 | B5: Delete whatever code is there, paste in the script I gave you (the .gs file), and click the Save icon.
A6: 4 | B6: Close the Apps Script tab and reload your Google Sheet. A new "💪 Workout" menu appears in the top bar.
A7: 5 | B7: First time you use it, Google asks you to authorize the script — approve it (it only touches this sheet).
B8: — Done. —
B9: HOW YOU USE IT EACH SESSION:
A10: • | B10: 💪 Workout → Start Today's Session → pick UA / LA / UB / LB.
A11: • | B11: The Today tab fills with that day's exercises, the target rep range, and a suggested weight (already bumped if you earned it last time).
A12: • | B12: Type the reps you actually hit in the Reps column. Adjust weight only if it differs from the suggestion.
A13: • | B13: 💪 Workout → Save Session. It files everything into the Log with today's date and refreshes the signals.
